## [2650.设计可取消函数 中文热门题解1](https://leetcode.cn/problems/design-cancellable-function/solutions/100000/generator-promise-bi-bao-by-fawinell-xkn8)

作者：[fawinell](https://leetcode.cn/u/fawinell)
## 复习一下 `generator`

1. 什么是  `generator` ？：

    简单的说就是可以中断的函数，该函数里的代码可以用 `yield` 关键字来中断。如何继续执行？看下面

2. 怎么定义一个  `generator` ：

    一般来说都用 `function*` 标识符来定义，例如
    ```javascript
    function* tasks() {
        const val = yield new Promise(resolve => resolve(2 + 2));
        yield new Promise(resolve => setTimeout(resolve, 100));
        return val + 1;
    }
    ```

3. `generator` 的实例，或者说返回值，有哪些方法？
    
    ```javascript
    function* tasks() {
        const val = yield new Promise(resolve => resolve(2 + 2));
        yield new Promise(resolve => setTimeout(resolve, 100));
        return val + 1;
    }
    const _t = tasks();
    ```
    
    总的来说有三种方法，`next`、`throw`, `return`。这三种方法都会返回一个 `IteratorResult`，也就是形如：
    ```ts
    interface IteratorResult {
        value: any;
        done: boolean
    }
    ```
    - `done` 则表示该 `generator` 是否完成，`true` 完成，`false` 未完成
    - `value` 不同方法调用代表的值不同，下面再说。

    那么 `generator` 啥时候完成？就是走到这个 `generator` 本身 `return` 的时候。

    下面开始介绍三个方法
    - `next` 方法：
        - 在 `next` 方法的返回值中，`IteratorResult` 中的 `value` 是 `yield` 关键词右侧代码的执行结果
        - `generator` 的执行必需由 `next` 方法开启，并走到 `yield` 关键词停止

        - 继续调用`next()` 可以在 `yield` 后继续往下走，走到下一个 `yield` 为止

        

        - 该方法同时支持传参，传入的参数会成为上一个 `yield` 的返回值，例如：
            ```js
            function* tasks() {
                const val = yield new Promise(resolve => resolve(2 + 2)); // 1
                console.log({val});
                yield new Promise(resolve => setTimeout(resolve, 100)); // 2
                return val + 1;
            }
            const _t = tasks();
            _t.next(); // 走到 1 处，返回的 {value， done} 中的 value 是 1 处的 Promise
            _t.next(100); // 走到 2 处，打印 val 为 100
            ```
    - `throw` 方法：
        - 在 `throw` 方法的返回值中，`IteratorResult` 中的 `value` 同样是 `yield` 关键词右侧代码的执行结果
        - 该方法通过传参抛出一个错误，如果该错误没有被 `generator` 本身 `catch` 住，则会往外暴露给外层，也就是    `generator` 的*调用方*。如果*调用方*也没有 `catch` 住，则正常抛错。
        - 例子1，被 `generator` 本身 `catch`：
            ```js
            function* tasks() {
                try {
                    const val = yield new Promise(resolve => resolve(2 + 2));
                } catch (err) {
                    console.log('catched by generator *tasks', err);
                }
                yield new Promise(resolve => setTimeout(resolve, 100));
                return val + 1;
            }
            const _t = tasks();
            _t.next();
            _t.throw('err 1');
            ```
        - 例子2，被 `generator` 的调用方 `catch`：
            ```js
            function* tasks() {
                const val = yield new Promise(resolve => resolve(2 + 2));
                yield new Promise(resolve => setTimeout(resolve, 100));
                return val + 1;
            }
            const _t = tasks();
            _t.next();
            try {
                _t.throw('err 2');
            } catch(err) {
                console.log('catched by generator *tasks caller', err);
            }
            ```
    - `return` 方法
        - 在 `return` 方法的返回值中，`IteratorResult` 中的 `value` 是 `return` 方法传递的参数
        - 该方法强制 `generator` 函数完成，其返回 `IteratorResult` 中的 `done` 将为 `true`
        - 举例
            ```js
            function* tasks() {
                const val = yield new Promise(resolve => resolve(2 + 2));
                yield new Promise(resolve => setTimeout(resolve, 100));
                return val + 1;
            }
            const _t = tasks();
            _t.next();
            const obj = _t.return('Return by Generator.return method');
            console.log(obj); // {value: 'Return by Generator.return method', done: true}
            ```

## 回到本题
1. 首先得返回一个数组，一个是 `function`，一个是 `Promise`
2. 其次我们要走完这个 `generator` 得不停的调用 `next` 方法。一般用 `while` 或者递归，这里我们涉及传参给下一个调用，所以要用递归
3. 我们有个 `cancel` 方法，根据题意，这个方法显然是要用 `throw` 方法的，并且其失败被 `generator` *调用方* 捕获时，要直接 `reject` 这个 `Promise`。所以要利用闭包定义在 `Promise` 中
4. `generator` 内部调用的 `Promise` 可能成功也可能失败，所以要处理成功、失败两种情况。对于这个 `Promise` 来说，成功的回调我们走 `next`，失败的回调我们应该 `throw`
5. `generator` 本身会抛出一个错误，所以要对 `next` 的运行进行 `try catch`，根据题意 `catch` 后我们要直接 `reject` 掉这个 `Promise`

```js
/**
 * @param {Generator} generator
 * @return {[Function, Promise]}
 */
var cancellable = function (generator) {
    let cancel = () => {};
    const p = new Promise((resolve, reject) => {
        cancel = (msg = 'Cancelled') => {
            run(msg, 'throw');
        };
        const run = (ret, fnName = 'next') => {
            try {
                const {value, done} = generator[fnName](ret);
                if (done) {
                    resolve(value);
                    return;
                }
                value.then((val) => {
                    run(val);
                }).catch((err) => {
                    run(err, 'throw');
                });
            } catch (errorByGenerator) {
                reject(errorByGenerator);
            }
        };
        run(null);
    });
    return [cancel, p];
};
```


难以想象如果面试问了这个题是什么场景。。感觉力扣开始搞这种题目了以后，以后会出现很多看了几篇文章或题解的"面试官"用这些提来为难面试者。。